<mujoco model="humanoid">
  <compiler coordinate="local" meshdir="assets" autolimits="true" angle="radian"/>
  <default>
    <joint damping="0.0" armature="0.01" stiffness="0.0" limited="true"/>
    <geom conaffinity="1" condim="3" contype="7" margin="0.001" rgba="0.8 0.6 .4 1"/>
  </default>
  <asset>
    <texture type="skybox" builtin="gradient" rgb1=".4 .5 .6" rgb2="0 0 0" width="100" height="100"/>
    <texture builtin="flat" height="1278" mark="cross" markrgb="1 1 1" name="texgeom" random="0.01" rgb1="0.8 0.6 0.4" rgb2="0.8 0.6 0.4" type="cube" width="127"/>
    <texture builtin="checker" height="100" name="texplane" rgb1="0 0 0" rgb2="0.8 0.8 0.8" type="2d" width="100"/>
    <material name="MatPlane" reflectance="0.5" shininess="1" specular="1" texrepeat="60 60" texture="texplane"/>
    <material name="geom" texture="texgeom" texuniform="true"/>
    <mesh file="Pelvis.stl" name="Pelvis_mesh"/>
    <mesh file="L_Hip.stl" name="L_Hip_mesh"/>
    <mesh file="R_Hip.stl" name="R_Hip_mesh"/>
    <mesh file="Torso.stl" name="Torso_mesh"/>
    <mesh file="L_Knee.stl" name="L_Knee_mesh"/>
    <mesh file="R_Knee.stl" name="R_Knee_mesh"/>
    <mesh file="Spine.stl" name="Spine_mesh"/>
    <mesh file="L_Ankle.stl" name="L_Ankle_mesh"/>
    <mesh file="R_Ankle.stl" name="R_Ankle_mesh"/>
    <mesh file="Chest.stl" name="Chest_mesh"/>
    <mesh file="L_Toe.stl" name="L_Toe_mesh"/>
    <mesh file="R_Toe.stl" name="R_Toe_mesh"/>
    <mesh file="Neck.stl" name="Neck_mesh"/>
    <mesh file="L_Thorax.stl" name="L_Thorax_mesh"/>
    <mesh file="R_Thorax.stl" name="R_Thorax_mesh"/>
    <mesh file="Head.stl" name="Head_mesh"/>
    <mesh file="L_Shoulder.stl" name="L_Shoulder_mesh"/>
    <mesh file="R_Shoulder.stl" name="R_Shoulder_mesh"/>
    <mesh file="L_Elbow.stl" name="L_Elbow_mesh"/>
    <mesh file="R_Elbow.stl" name="R_Elbow_mesh"/>
    <mesh file="L_Wrist.stl" name="L_Wrist_mesh"/>
    <mesh file="R_Wrist.stl" name="R_Wrist_mesh"/>
    <mesh file="L_Hand.stl" name="L_Hand_mesh"/>
    <mesh file="R_Hand.stl" name="R_Hand_mesh"/>
  </asset>
  <worldbody>
    <light cutoff="100" diffuse="1 1 1" dir="-0 0 -1.3" directional="true" exponent="1" pos="0 0 1.3" specular=".1 .1 .1"/>
    <body name="Pelvis" pos="-0.0048 -0.1882 0.0121">
      <freejoint name="Pelvis"/>
      <geom type="mesh" mesh="Pelvis_mesh" density="1000" contype="1" conaffinity="1"/>
      <body name="L_Hip" pos="0.033 -0.0879 -0.0124">
        <joint name="L_Hip_x" type="hinge" pos="0 0 0" axis="1 0 0" user="800 80 1 500" armature="0.01" range="-1.57 1.57" damping="0.1" stiffness="100"/>
        <joint name="L_Hip_y" type="hinge" pos="0 0 0" axis="0 1 0" user="800 80 1 500" armature="0.01" range="-1.57 1.57" damping="0.1" stiffness="100"/>
        <joint name="L_Hip_z" type="hinge" pos="0 0 0" axis="0 0 1" user="800 80 1 500" armature="0.01" range="-1.57 1.57" damping="0.1" stiffness="100"/>
        <geom type="mesh" mesh="L_Hip_mesh" density="1000" contype="1" conaffinity="1"/>
        <body name="L_Knee" pos="0.1242 -0.3536 0.0442">
          <joint name="L_Knee_x" type="hinge" pos="0 0 0" axis="1 0 0" user="800 80 1 500" armature="0.01" range="-1.57 1.57" damping="0.1" stiffness="100"/>
          <joint name="L_Knee_y" type="hinge" pos="0 0 0" axis="0 1 0" user="800 80 1 500" armature="0.01" range="-1.57 1.57" damping="0.1" stiffness="100"/>
          <joint name="L_Knee_z" type="hinge" pos="0 0 0" axis="0 0 1" user="800 80 1 500" armature="0.01" range="-1.57 1.57" damping="0.1" stiffness="100"/>
          <geom type="mesh" mesh="L_Knee_mesh" density="1000" contype="1" conaffinity="1"/>
          <body name="L_Ankle" pos="0.1224 -0.3668 -0.0704">
            <joint name="L_Ankle_x" type="hinge" pos="0 0 0" axis="1 0 0" user="800 80 1 500" armature="0.01" range="-1.57 1.57" damping="0.1" stiffness="100"/>
            <joint name="L_Ankle_y" type="hinge" pos="0 0 0" axis="0 1 0" user="800 80 1 500" armature="0.01" range="-1.57 1.57" damping="0.1" stiffness="100"/>
            <joint name="L_Ankle_z" type="hinge" pos="0 0 0" axis="0 0 1" user="800 80 1 500" armature="0.01" range="-1.57 1.57" damping="0.1" stiffness="100"/>
            <geom density="338.2488" type="box" pos="0.0108 -0.0277 0.0321" size="0.0506 0.0472 0.0796" quat="1.0000 0.0000 0.0000 0.0000"/>
            <body name="L_Toe" pos="-0.0077 -0.0701 0.1057">
              <joint name="L_Toe_x" type="hinge" pos="0 0 0" axis="1 0 0" user="500 50 1 500" armature="0.01" range="-1.57 1.57" damping="0.1" stiffness="100"/>
              <joint name="L_Toe_y" type="hinge" pos="0 0 0" axis="0 1 0" user="500 50 1 500" armature="0.01" range="-1.57 1.57" damping="0.1" stiffness="100"/>
              <joint name="L_Toe_z" type="hinge" pos="0 0 0" axis="0 0 1" user="500 50 1 500" armature="0.01" range="-1.57 1.57" damping="0.1" stiffness="100"/>
              <geom density="297.8384" type="box" pos="0.0185 0.0203 0.0131" size="0.0503 0.0251 0.0394" quat="1.0000 0.0000 0.0000 0.0000"/>
            </body>
          </body>
        </body>
      </body>
      <body name="R_Hip" pos="-0.0633 -0.0678 -0.0103">
        <joint name="R_Hip_x" type="hinge" pos="0 0 0" axis="1 0 0" user="800 80 1 500" armature="0.01" range="-1.57 1.57" damping="0.1" stiffness="100"/>
        <joint name="R_Hip_y" type="hinge" pos="0 0 0" axis="0 1 0" user="800 80 1 500" armature="0.01" range="-1.57 1.57" damping="0.1" stiffness="100"/>
        <joint name="R_Hip_z" type="hinge" pos="0 0 0" axis="0 0 1" user="800 80 1 500" armature="0.01" range="-1.57 1.57" damping="0.1" stiffness="100"/>
        <geom type="mesh" mesh="R_Hip_mesh" density="1000" contype="1" conaffinity="1"/>
        <body name="R_Knee" pos="-0.128 -0.3417 0.1173">
          <joint name="R_Knee_x" type="hinge" pos="0 0 0" axis="1 0 0" user="800 80 1 500" armature="0.01" range="-1.57 1.57" damping="0.1" stiffness="100"/>
          <joint name="R_Knee_y" type="hinge" pos="0 0 0" axis="0 1 0" user="800 80 1 500" armature="0.01" range="-1.57 1.57" damping="0.1" stiffness="100"/>
          <joint name="R_Knee_z" type="hinge" pos="0 0 0" axis="0 0 1" user="800 80 1 500" armature="0.01" range="-1.57 1.57" damping="0.1" stiffness="100"/>
          <geom type="mesh" mesh="R_Knee_mesh" density="1000" contype="1" conaffinity="1"/>
          <body name="R_Ankle" pos="-0.1573 -0.3184 -0.1645">
            <joint name="R_Ankle_x" type="hinge" pos="0 0 0" axis="1 0 0" user="800 80 1 500" armature="0.01" range="-1.57 1.57" damping="0.1" stiffness="100"/>
            <joint name="R_Ankle_y" type="hinge" pos="0 0 0" axis="0 1 0" user="800 80 1 500" armature="0.01" range="-1.57 1.57" damping="0.1" stiffness="100"/>
            <joint name="R_Ankle_z" type="hinge" pos="0 0 0" axis="0 0 1" user="800 80 1 500" armature="0.01" range="-1.57 1.57" damping="0.1" stiffness="100"/>
            <geom density="332.62534" type="box" pos="-0.0159 -0.0311 0.0154" size="0.0417 0.0656 0.0726" quat="1.0000 0.0000 0.0000 0.0000"/>
            <body name="R_Toe" pos="-0.0153 -0.0847 0.0915">
              <joint name="R_Toe_x" type="hinge" pos="0 0 0" axis="1 0 0" user="500 50 1 500" armature="0.01" range="-1.57 1.57" damping="0.1" stiffness="100"/>
              <joint name="R_Toe_y" type="hinge" pos="0 0 0" axis="0 1 0" user="500 50 1 500" armature="0.01" range="-1.57 1.57" damping="0.1" stiffness="100"/>
              <joint name="R_Toe_z" type="hinge" pos="0 0 0" axis="0 0 1" user="500 50 1 500" armature="0.01" range="-1.57 1.57" damping="0.1" stiffness="100"/>
              <geom density="248.7737" type="box" pos="-0.0005 0.0235 0.0140" size="0.0429 0.0355 0.0416" quat="1.0000 0.0000 0.0000 0.0000"/>
            </body>
          </body>
        </body>
      </body>
      <body name="Torso" pos="0.0162 0.0944 -0.0136">
        <joint name="Torso_x" type="hinge" pos="0 0 0" axis="1 0 0" user="1000 100 1 500" armature="0.01" range="-60.0000 60.0000" damping="0.1" stiffness="100"/>
        <joint name="Torso_y" type="hinge" pos="0 0 0" axis="0 1 0" user="1000 100 1 500" armature="0.01" range="-60.0000 60.0000" damping="0.1" stiffness="100"/>
        <joint name="Torso_z" type="hinge" pos="0 0 0" axis="0 0 1" user="1000 100 1 500" armature="0.01" range="-60.0000 60.0000" damping="0.1" stiffness="100"/>
        <geom type="mesh" mesh="Torso_mesh" density="1000" contype="1" conaffinity="1"/>
        <body name="Spine" pos="0.0318 0.1232 0.0073">
          <joint name="Spine_x" type="hinge" pos="0 0 0" axis="1 0 0" user="1000 100 1 500" armature="0.01" range="-60.0000 60.0000" damping="0.1" stiffness="100"/>
          <joint name="Spine_y" type="hinge" pos="0 0 0" axis="0 1 0" user="1000 100 1 500" armature="0.01" range="-60.0000 60.0000" damping="0.1" stiffness="100"/>
          <joint name="Spine_z" type="hinge" pos="0 0 0" axis="0 0 1" user="1000 100 1 500" armature="0.01" range="-60.0000 60.0000" damping="0.1" stiffness="100"/>
          <geom type="mesh" mesh="Spine_mesh" density="1000" contype="1" conaffinity="1"/>
          <body name="Chest" pos="0.0112 0.0455 0.0146">
            <joint name="Chest_x" type="hinge" pos="0 0 0" axis="1 0 0" user="1000 100 1 500" armature="0.01" range="-60.0000 60.0000" damping="0.1" stiffness="100"/>
            <joint name="Chest_y" type="hinge" pos="0 0 0" axis="0 1 0" user="1000 100 1 500" armature="0.01" range="-60.0000 60.0000" damping="0.1" stiffness="100"/>
            <joint name="Chest_z" type="hinge" pos="0 0 0" axis="0 0 1" user="1000 100 1 500" armature="0.01" range="-60.0000 60.0000" damping="0.1" stiffness="100"/>
            <geom type="mesh" mesh="Chest_mesh" density="1000" contype="1" conaffinity="1"/>
            <body name="Neck" pos="0.0305 0.1759 -0.02">
              <joint name="Neck_x" type="hinge" pos="0 0 0" axis="1 0 0" user="500 50 1 250" armature="0.01" range="-1.57 1.57" damping="0.1" stiffness="100"/>
              <joint name="Neck_y" type="hinge" pos="0 0 0" axis="0 1 0" user="500 50 1 250" armature="0.01" range="-1.57 1.57" damping="0.1" stiffness="100"/>
              <joint name="Neck_z" type="hinge" pos="0 0 0" axis="0 0 1" user="500 50 1 250" armature="0.01" range="-1.57 1.57" damping="0.1" stiffness="100"/>
              <geom type="mesh" mesh="Neck_mesh" density="1000" contype="1" conaffinity="1"/>
              <body name="Head" pos="0.0194 0.0616 0.0498">
                <joint name="Head_x" type="hinge" pos="0 0 0" axis="1 0 0" user="500 50 1 250" armature="0.01" range="-1.57 1.57" damping="0.1" stiffness="100"/>
                <joint name="Head_y" type="hinge" pos="0 0 0" axis="0 1 0" user="500 50 1 250" armature="0.01" range="-1.57 1.57" damping="0.1" stiffness="100"/>
                <joint name="Head_z" type="hinge" pos="0 0 0" axis="0 0 1" user="500 50 1 250" armature="0.01" range="-1.57 1.57" damping="0.1" stiffness="100"/>
                <geom type="mesh" mesh="Head_mesh" density="1000" contype="1" conaffinity="1"/>
              </body>
            </body>
            <body name="L_Thorax" pos="0.0866 0.0868 -0.0242">
              <joint name="L_Thorax_x" type="hinge" pos="0 0 0" axis="1 0 0" user="500 50 1 500" armature="0.01" range="-1.57 1.57" damping="0.1" stiffness="100"/>
              <joint name="L_Thorax_y" type="hinge" pos="0 0 0" axis="0 1 0" user="500 50 1 500" armature="0.01" range="-1.57 1.57" damping="0.1" stiffness="100"/>
              <joint name="L_Thorax_z" type="hinge" pos="0 0 0" axis="0 0 1" user="500 50 1 500" armature="0.01" range="-1.57 1.57" damping="0.1" stiffness="100"/>
              <geom type="mesh" mesh="L_Thorax_mesh" density="1000" contype="1" conaffinity="1"/>
              <body name="L_Shoulder" pos="0.0857 -0.0116 0.0032">
                <joint name="L_Shoulder_x" type="hinge" pos="0 0 0" axis="1 0 0" user="500 50 1 500" armature="0.01" range="-1.57 1.57" damping="0.1" stiffness="100"/>
                <joint name="L_Shoulder_y" type="hinge" pos="0 0 0" axis="0 1 0" user="500 50 1 500" armature="0.01" range="-1.57 1.57" damping="0.1" stiffness="100"/>
                <joint name="L_Shoulder_z" type="hinge" pos="0 0 0" axis="0 0 1" user="500 50 1 500" armature="0.01" range="-1.57 1.57" damping="0.1" stiffness="100"/>
                <geom type="mesh" mesh="L_Shoulder_mesh" density="1000" contype="1" conaffinity="1"/>
                <body name="L_Elbow" pos="0.1302 -0.191 -0.1052">
                  <joint name="L_Elbow_x" type="hinge" pos="0 0 0" axis="1 0 0" user="500 50 1 150" armature="0.01" range="-720.0000 720.0000" damping="0.1" stiffness="100"/>
                  <joint name="L_Elbow_y" type="hinge" pos="0 0 0" axis="0 1 0" user="500 50 1 150" armature="0.01" range="-720.0000 720.0000" damping="0.1" stiffness="100"/>
                  <joint name="L_Elbow_z" type="hinge" pos="0 0 0" axis="0 0 1" user="500 50 1 150" armature="0.01" range="-720.0000 720.0000" damping="0.1" stiffness="100"/>
                  <geom type="mesh" mesh="L_Elbow_mesh" density="1000" contype="1" conaffinity="1"/>
                  <body name="L_Wrist" pos="0.0497 -0.2029 0.1247">
                    <joint name="L_Wrist_x" type="hinge" pos="0 0 0" axis="1 0 0" user="300 30 1 150" armature="0.01" range="-1.57 1.57" damping="0.1" stiffness="100"/>
                    <joint name="L_Wrist_y" type="hinge" pos="0 0 0" axis="0 1 0" user="300 30 1 150" armature="0.01" range="-1.57 1.57" damping="0.1" stiffness="100"/>
                    <joint name="L_Wrist_z" type="hinge" pos="0 0 0" axis="0 0 1" user="300 30 1 150" armature="0.01" range="-1.57 1.57" damping="0.1" stiffness="100"/>
                    <geom type="mesh" mesh="L_Wrist_mesh" density="1000" contype="1" conaffinity="1"/>
                    <body name="L_Hand" pos="0.0151 -0.0734 0.0257">
                      <joint name="L_Hand_x" type="hinge" pos="0 0 0" axis="1 0 0" user="300 30 1 150" armature="0.01" range="-1.57 1.57" damping="0.1" stiffness="100"/>
                      <joint name="L_Hand_y" type="hinge" pos="0 0 0" axis="0 1 0" user="300 30 1 150" armature="0.01" range="-1.57 1.57" damping="0.1" stiffness="100"/>
                      <joint name="L_Hand_z" type="hinge" pos="0 0 0" axis="0 0 1" user="300 30 1 150" armature="0.01" range="-1.57 1.57" damping="0.1" stiffness="100"/>
                      <geom type="mesh" mesh="L_Hand_mesh" density="1000" contype="1" conaffinity="1"/>
                    </body>
                  </body>
                </body>
              </body>
            </body>
            <body name="R_Thorax" pos="-0.0497 0.1114 -0.0284">
              <joint name="R_Thorax_x" type="hinge" pos="0 0 0" axis="1 0 0" user="500 50 1 150" armature="0.01" range="-1.57 1.57" damping="0.1" stiffness="100"/>
              <joint name="R_Thorax_y" type="hinge" pos="0 0 0" axis="0 1 0" user="500 50 1 150" armature="0.01" range="-1.57 1.57" damping="0.1" stiffness="100"/>
              <joint name="R_Thorax_z" type="hinge" pos="0 0 0" axis="0 0 1" user="500 50 1 150" armature="0.01" range="-1.57 1.57" damping="0.1" stiffness="100"/>
              <geom type="mesh" mesh="R_Thorax_mesh" density="1000" contype="1" conaffinity="1"/>
              <body name="R_Shoulder" pos="-0.085 0.0199 -0.0234">
                <joint name="R_Shoulder_x" type="hinge" pos="0 0 0" axis="1 0 0" user="500 50 1 250" armature="0.01" range="-1.57 1.57" damping="0.1" stiffness="100"/>
                <joint name="R_Shoulder_y" type="hinge" pos="0 0 0" axis="0 1 0" user="500 50 1 250" armature="0.01" range="-1.57 1.57" damping="0.1" stiffness="100"/>
                <joint name="R_Shoulder_z" type="hinge" pos="0 0 0" axis="0 0 1" user="500 50 1 250" armature="0.01" range="-1.57 1.57" damping="0.1" stiffness="100"/>
                <geom type="mesh" mesh="R_Shoulder_mesh" density="1000" contype="1" conaffinity="1"/>
                <body name="R_Elbow" pos="-0.1718 -0.1671 -0.0249">
                  <joint name="R_Elbow_x" type="hinge" pos="0 0 0" axis="1 0 0" user="500 50 1 150" armature="0.01" range="-720.0000 720.0000" damping="0.1" stiffness="100"/>
                  <joint name="R_Elbow_y" type="hinge" pos="0 0 0" axis="0 1 0" user="500 50 1 150" armature="0.01" range="-720.0000 720.0000" damping="0.1" stiffness="100"/>
                  <joint name="R_Elbow_z" type="hinge" pos="0 0 0" axis="0 0 1" user="500 50 1 150" armature="0.01" range="-720.0000 720.0000" damping="0.1" stiffness="100"/>
                  <geom type="mesh" mesh="R_Elbow_mesh" density="1000" contype="1" conaffinity="1"/>
                  <body name="R_Wrist" pos="-0.212 -0.1288 -0.004">
                    <joint name="R_Wrist_x" type="hinge" pos="0 0 0" axis="1 0 0" user="300 30 1 150" armature="0.01" range="-1.57 1.57" damping="0.1" stiffness="100"/>
                    <joint name="R_Wrist_y" type="hinge" pos="0 0 0" axis="0 1 0" user="300 30 1 150" armature="0.01" range="-1.57 1.57" damping="0.1" stiffness="100"/>
                    <joint name="R_Wrist_z" type="hinge" pos="0 0 0" axis="0 0 1" user="300 30 1 150" armature="0.01" range="-1.57 1.57" damping="0.1" stiffness="100"/>
                    <geom type="mesh" mesh="R_Wrist_mesh" density="1000" contype="1" conaffinity="1"/>
                    <body name="R_Hand" pos="-0.0615 -0.0475 -0.0005">
                      <joint name="R_Hand_x" type="hinge" pos="0 0 0" axis="1 0 0" user="300 30 1 150" armature="0.01" range="-1.57 1.57" damping="0.1" stiffness="100"/>
                      <joint name="R_Hand_y" type="hinge" pos="0 0 0" axis="0 1 0" user="300 30 1 150" armature="0.01" range="-1.57 1.57" damping="0.1" stiffness="100"/>
                      <joint name="R_Hand_z" type="hinge" pos="0 0 0" axis="0 0 1" user="300 30 1 150" armature="0.01" range="-1.57 1.57" damping="0.1" stiffness="100"/>
                      <geom type="mesh" mesh="R_Hand_mesh" density="1000" contype="1" conaffinity="1"/>
                    </body>
                  </body>
                </body>
              </body>
            </body>
          </body>
        </body>
      </body>
    </body>
  </worldbody>
  <actuator>
    <motor name="L_Hip_x" joint="L_Hip_x" gear="1"/>
    <motor name="L_Hip_y" joint="L_Hip_y" gear="1"/>
    <motor name="L_Hip_z" joint="L_Hip_z" gear="1"/>
    <motor name="L_Knee_x" joint="L_Knee_x" gear="1"/>
    <motor name="L_Knee_y" joint="L_Knee_y" gear="1"/>
    <motor name="L_Knee_z" joint="L_Knee_z" gear="1"/>
    <motor name="L_Ankle_x" joint="L_Ankle_x" gear="1"/>
    <motor name="L_Ankle_y" joint="L_Ankle_y" gear="1"/>
    <motor name="L_Ankle_z" joint="L_Ankle_z" gear="1"/>
    <motor name="L_Toe_x" joint="L_Toe_x" gear="1"/>
    <motor name="L_Toe_y" joint="L_Toe_y" gear="1"/>
    <motor name="L_Toe_z" joint="L_Toe_z" gear="1"/>
    <motor name="R_Hip_x" joint="R_Hip_x" gear="1"/>
    <motor name="R_Hip_y" joint="R_Hip_y" gear="1"/>
    <motor name="R_Hip_z" joint="R_Hip_z" gear="1"/>
    <motor name="R_Knee_x" joint="R_Knee_x" gear="1"/>
    <motor name="R_Knee_y" joint="R_Knee_y" gear="1"/>
    <motor name="R_Knee_z" joint="R_Knee_z" gear="1"/>
    <motor name="R_Ankle_x" joint="R_Ankle_x" gear="1"/>
    <motor name="R_Ankle_y" joint="R_Ankle_y" gear="1"/>
    <motor name="R_Ankle_z" joint="R_Ankle_z" gear="1"/>
    <motor name="R_Toe_x" joint="R_Toe_x" gear="1"/>
    <motor name="R_Toe_y" joint="R_Toe_y" gear="1"/>
    <motor name="R_Toe_z" joint="R_Toe_z" gear="1"/>
    <motor name="Torso_x" joint="Torso_x" gear="1"/>
    <motor name="Torso_y" joint="Torso_y" gear="1"/>
    <motor name="Torso_z" joint="Torso_z" gear="1"/>
    <motor name="Spine_x" joint="Spine_x" gear="1"/>
    <motor name="Spine_y" joint="Spine_y" gear="1"/>
    <motor name="Spine_z" joint="Spine_z" gear="1"/>
    <motor name="Chest_x" joint="Chest_x" gear="1"/>
    <motor name="Chest_y" joint="Chest_y" gear="1"/>
    <motor name="Chest_z" joint="Chest_z" gear="1"/>
    <motor name="Neck_x" joint="Neck_x" gear="1"/>
    <motor name="Neck_y" joint="Neck_y" gear="1"/>
    <motor name="Neck_z" joint="Neck_z" gear="1"/>
    <motor name="Head_x" joint="Head_x" gear="1"/>
    <motor name="Head_y" joint="Head_y" gear="1"/>
    <motor name="Head_z" joint="Head_z" gear="1"/>
    <motor name="L_Thorax_x" joint="L_Thorax_x" gear="1"/>
    <motor name="L_Thorax_y" joint="L_Thorax_y" gear="1"/>
    <motor name="L_Thorax_z" joint="L_Thorax_z" gear="1"/>
    <motor name="L_Shoulder_x" joint="L_Shoulder_x" gear="1"/>
    <motor name="L_Shoulder_y" joint="L_Shoulder_y" gear="1"/>
    <motor name="L_Shoulder_z" joint="L_Shoulder_z" gear="1"/>
    <motor name="L_Elbow_x" joint="L_Elbow_x" gear="1"/>
    <motor name="L_Elbow_y" joint="L_Elbow_y" gear="1"/>
    <motor name="L_Elbow_z" joint="L_Elbow_z" gear="1"/>
    <motor name="L_Wrist_x" joint="L_Wrist_x" gear="1"/>
    <motor name="L_Wrist_y" joint="L_Wrist_y" gear="1"/>
    <motor name="L_Wrist_z" joint="L_Wrist_z" gear="1"/>
    <motor name="L_Hand_x" joint="L_Hand_x" gear="1"/>
    <motor name="L_Hand_y" joint="L_Hand_y" gear="1"/>
    <motor name="L_Hand_z" joint="L_Hand_z" gear="1"/>
    <motor name="R_Thorax_x" joint="R_Thorax_x" gear="1"/>
    <motor name="R_Thorax_y" joint="R_Thorax_y" gear="1"/>
    <motor name="R_Thorax_z" joint="R_Thorax_z" gear="1"/>
    <motor name="R_Shoulder_x" joint="R_Shoulder_x" gear="1"/>
    <motor name="R_Shoulder_y" joint="R_Shoulder_y" gear="1"/>
    <motor name="R_Shoulder_z" joint="R_Shoulder_z" gear="1"/>
    <motor name="R_Elbow_x" joint="R_Elbow_x" gear="1"/>
    <motor name="R_Elbow_y" joint="R_Elbow_y" gear="1"/>
    <motor name="R_Elbow_z" joint="R_Elbow_z" gear="1"/>
    <motor name="R_Wrist_x" joint="R_Wrist_x" gear="1"/>
    <motor name="R_Wrist_y" joint="R_Wrist_y" gear="1"/>
    <motor name="R_Wrist_z" joint="R_Wrist_z" gear="1"/>
    <motor name="R_Hand_x" joint="R_Hand_x" gear="1"/>
    <motor name="R_Hand_y" joint="R_Hand_y" gear="1"/>
    <motor name="R_Hand_z" joint="R_Hand_z" gear="1"/>
  </actuator>
  <contact>
    <exclude body1="Torso" body2="Chest"/>
    <exclude body1="Head" body2="Chest"/>
    <exclude body1="R_Knee" body2="R_Toe"/>
    <exclude body1="R_Knee" body2="L_Ankle"/>
    <exclude body1="R_Knee" body2="L_Toe"/>
    <exclude body1="L_Knee" body2="L_Toe"/>
    <exclude body1="L_Knee" body2="R_Ankle"/>
    <exclude body1="L_Knee" body2="R_Toe"/>
    <exclude body1="L_Shoulder" body2="Chest"/>
    <exclude body1="R_Shoulder" body2="Chest"/>
  </contact>
  <sensor/>
  <size njmax="2500" nconmax="500"/>
</mujoco>
