<?xml version='1.0' encoding='UTF-8'?>
<mujoco model="humanoid">
  <compiler coordinate="local" meshdir="assets" />
  <default>
    <joint damping="0.1" armature="0.01" stiffness="100.0" limited="true" />
    <geom conaffinity="1" condim="3" contype="7" margin="0.001" rgba="0.8 0.6 .4 1" type="box" size="0.01 0.01 0.01" />
  </default>
  <asset>
    <texture type="skybox" builtin="gradient" rgb1=".4 .5 .6" rgb2="0 0 0" width="100" height="100" />
    <texture builtin="flat" height="1278" mark="cross" markrgb="1 1 1" name="texgeom" random="0.01" rgb1="0.8 0.6 0.4" rgb2="0.8 0.6 0.4" type="cube" width="127" />
    <texture builtin="checker" height="100" name="texplane" rgb1="0 0 0" rgb2="0.8 0.8 0.8" type="2d" width="100" />
    <material name="MatPlane" reflectance="0.5" shininess="1" specular="1" texrepeat="60 60" texture="texplane" />
    <material name="geom" texture="texgeom" texuniform="true" />
    <mesh file="Pelvis.stl" name="Pelvis_mesh" />
    <mesh file="L_Hip.stl" name="L_Hip_mesh" />
    <mesh file="R_Hip.stl" name="R_Hip_mesh" />
    <mesh file="Torso.stl" name="Torso_mesh" />
    <mesh file="L_Knee.stl" name="L_Knee_mesh" />
    <mesh file="R_Knee.stl" name="R_Knee_mesh" />
    <mesh file="Spine.stl" name="Spine_mesh" />
    <mesh file="L_Ankle.stl" name="L_Ankle_mesh" />
    <mesh file="R_Ankle.stl" name="R_Ankle_mesh" />
    <mesh file="Chest.stl" name="Chest_mesh" />
    <mesh file="L_Toe.stl" name="L_Toe_mesh" />
    <mesh file="R_Toe.stl" name="R_Toe_mesh" />
    <mesh file="Neck.stl" name="Neck_mesh" />
    <mesh file="L_Thorax.stl" name="L_Thorax_mesh" />
    <mesh file="R_Thorax.stl" name="R_Thorax_mesh" />
    <mesh file="Head.stl" name="Head_mesh" />
    <mesh file="L_Shoulder.stl" name="L_Shoulder_mesh" />
    <mesh file="R_Shoulder.stl" name="R_Shoulder_mesh" />
    <mesh file="L_Elbow.stl" name="L_Elbow_mesh" />
    <mesh file="R_Elbow.stl" name="R_Elbow_mesh" />
    <mesh file="L_Wrist.stl" name="L_Wrist_mesh" />
    <mesh file="R_Wrist.stl" name="R_Wrist_mesh" />
    <mesh file="L_Hand.stl" name="L_Hand_mesh" />
    <mesh file="R_Hand.stl" name="R_Hand_mesh" />
  </asset>
  <worldbody>
    <light cutoff="100" diffuse="1 1 1" dir="-0 0 -1.3" directional="true" exponent="1" pos="0 0 1.3" specular=".1 .1 .1" />
    <geom conaffinity="1" condim="3" name="floor" pos="0 0 0" rgba="0.8 0.9 0.8 1" size="100 100 .2" type="plane" material="MatPlane" />
    <body name="Pelvis" pos="-0.0015 -0.211 0.0427">
      <freejoint name="Pelvis" />
      <geom type="mesh" mesh="Pelvis_mesh" density="1000" contype="1" conaffinity="1" />
      <body name="L_Hip" pos="0.0748 -0.0975 -0.0052">
        <joint name="L_Hip_x" type="hinge" pos="0 0 0" axis="1 0 0" user="800 80 1 500" armature="0.01" range="-90.0000 90.0000" damping="0.1" stiffness="10" />
        <joint name="L_Hip_y" type="hinge" pos="0 0 0" axis="0 1 0" user="800 80 1 500" armature="0.01" range="-90.0000 90.0000" damping="0.1" stiffness="10" />
        <joint name="L_Hip_z" type="hinge" pos="0 0 0" axis="0 0 1" user="800 80 1 500" armature="0.01" range="-90.0000 90.0000" damping="0.1" stiffness="10" />
        <geom type="mesh" mesh="L_Hip_mesh" density="1000" contype="1" conaffinity="1" />
        <body name="L_Knee" pos="0.1895 -0.3461 0.0433">
          <joint name="L_Knee_x" type="hinge" pos="0 0 0" axis="1 0 0" user="800 80 1 500" armature="0.01" range="-180.0000 180.0000" damping="0.1" stiffness="10" />
          <joint name="L_Knee_y" type="hinge" pos="0 0 0" axis="0 1 0" user="800 80 1 500" armature="0.01" range="-5.6250 5.6250" damping="0.1" stiffness="10" />
          <joint name="L_Knee_z" type="hinge" pos="0 0 0" axis="0 0 1" user="800 80 1 500" armature="0.01" range="-5.6250 5.6250" damping="0.1" stiffness="10" />
          <geom type="mesh" mesh="L_Knee_mesh" density="1000" contype="1" conaffinity="1" />
          <body name="L_Ankle" pos="0.157 -0.3946 -0.0955">
            <joint name="L_Ankle_x" type="hinge" pos="0 0 0" axis="1 0 0" user="800 80 1 500" armature="0.01" range="-90.0000 90.0000" damping="0.1" stiffness="10" />
            <joint name="L_Ankle_y" type="hinge" pos="0 0 0" axis="0 1 0" user="800 80 1 500" armature="0.01" range="-90.0000 90.0000" damping="0.1" stiffness="10" />
            <joint name="L_Ankle_z" type="hinge" pos="0 0 0" axis="0 0 1" user="800 80 1 500" armature="0.01" range="-90.0000 90.0000" damping="0.1" stiffness="10" />
            <geom density="363.8337" type="box" pos="0.0395 -0.0241 0.0171" size="0.0652 0.0515 0.0872" quat="1.0000 0.0000 0.0000 0.0000" />
            <body name="L_Toe" pos="0.064 -0.0577 0.1106">
              <joint name="L_Toe_x" type="hinge" pos="0 0 0" axis="1 0 0" user="500 50 1 500" armature="0.01" range="-90.0000 90.0000" damping="0.1" stiffness="10" />
              <joint name="L_Toe_y" type="hinge" pos="0 0 0" axis="0 1 0" user="500 50 1 500" armature="0.01" range="-45.0000 45.0000" damping="0.1" stiffness="10" />
              <joint name="L_Toe_z" type="hinge" pos="0 0 0" axis="0 0 1" user="500 50 1 500" armature="0.01" range="-45.0000 45.0000" damping="0.1" stiffness="10" />
              <geom density="312.2989" type="box" pos="-0.0245 0.0125 0.0245" size="0.0491 0.0303 0.0547" quat="1.0000 0.0000 0.0000 0.0000" />
            </body>
          </body>
        </body>
      </body>
      <body name="R_Hip" pos="-0.0824 -0.0905 -0.0033">
        <joint name="R_Hip_x" type="hinge" pos="0 0 0" axis="1 0 0" user="800 80 1 500" armature="0.01" range="-90.0000 90.0000" damping="0.1" stiffness="10" />
        <joint name="R_Hip_y" type="hinge" pos="0 0 0" axis="0 1 0" user="800 80 1 500" armature="0.01" range="-90.0000 90.0000" damping="0.1" stiffness="10" />
        <joint name="R_Hip_z" type="hinge" pos="0 0 0" axis="0 0 1" user="800 80 1 500" armature="0.01" range="-90.0000 90.0000" damping="0.1" stiffness="10" />
        <geom type="mesh" mesh="R_Hip_mesh" density="1000" contype="1" conaffinity="1" />
        <body name="R_Knee" pos="-0.1774 -0.3003 0.2061">
          <joint name="R_Knee_x" type="hinge" pos="0 0 0" axis="1 0 0" user="800 80 1 500" armature="0.01" range="-180.0000 180.0000" damping="0.1" stiffness="10" />
          <joint name="R_Knee_y" type="hinge" pos="0 0 0" axis="0 1 0" user="800 80 1 500" armature="0.01" range="-5.6250 5.6250" damping="0.1" stiffness="10" />
          <joint name="R_Knee_z" type="hinge" pos="0 0 0" axis="0 0 1" user="800 80 1 500" armature="0.01" range="-5.6250 5.6250" damping="0.1" stiffness="10" />
          <geom type="mesh" mesh="R_Knee_mesh" density="1000" contype="1" conaffinity="1" />
          <body name="R_Ankle" pos="-0.1352 -0.1846 -0.3725">
            <joint name="R_Ankle_x" type="hinge" pos="0 0 0" axis="1 0 0" user="800 80 1 500" armature="0.01" range="-90.0000 90.0000" damping="0.1" stiffness="10" />
            <joint name="R_Ankle_y" type="hinge" pos="0 0 0" axis="0 1 0" user="800 80 1 500" armature="0.01" range="-90.0000 90.0000" damping="0.1" stiffness="10" />
            <joint name="R_Ankle_z" type="hinge" pos="0 0 0" axis="0 0 1" user="800 80 1 500" armature="0.01" range="-90.0000 90.0000" damping="0.1" stiffness="10" />
            <geom density="298.13422" type="box" pos="-0.0411 -0.0329 -0.0117" size="0.0704 0.0868 0.0573" quat="1.0000 0.0000 0.0000 0.0000" />
            <body name="R_Toe" pos="-0.0789 -0.1116 -0.0352">
              <joint name="R_Toe_x" type="hinge" pos="0 0 0" axis="1 0 0" user="500 50 1 500" armature="0.01" range="-90.0000 90.0000" damping="0.1" stiffness="10" />
              <joint name="R_Toe_y" type="hinge" pos="0 0 0" axis="0 1 0" user="500 50 1 500" armature="0.01" range="-45.0000 45.0000" damping="0.1" stiffness="10" />
              <joint name="R_Toe_z" type="hinge" pos="0 0 0" axis="0 0 1" user="500 50 1 500" armature="0.01" range="-45.0000 45.0000" damping="0.1" stiffness="10" />
              <geom density="406.3886" type="box" pos="0.0378 0.0477 0.0031" size="0.0476 0.0558 0.0241" quat="1.0000 0.0000 0.0000 0.0000" />
            </body>
          </body>
        </body>
      </body>
      <body name="Torso" pos="0.0035 0.1118 -0.0291">
        <joint name="Torso_x" type="hinge" pos="0 0 0" axis="1 0 0" user="1000 100 1 500" armature="0.01" range="-60.0000 60.0000" damping="0.1" stiffness="10" />
        <joint name="Torso_y" type="hinge" pos="0 0 0" axis="0 1 0" user="1000 100 1 500" armature="0.01" range="-60.0000 60.0000" damping="0.1" stiffness="10" />
        <joint name="Torso_z" type="hinge" pos="0 0 0" axis="0 0 1" user="1000 100 1 500" armature="0.01" range="-60.0000 60.0000" damping="0.1" stiffness="10" />
        <geom type="mesh" mesh="Torso_mesh" density="1000" contype="1" conaffinity="1" />
        <body name="Spine" pos="0.0097 0.116 0.005">
          <joint name="Spine_x" type="hinge" pos="0 0 0" axis="1 0 0" user="1000 100 1 500" armature="0.01" range="-60.0000 60.0000" damping="0.1" stiffness="10" />
          <joint name="Spine_y" type="hinge" pos="0 0 0" axis="0 1 0" user="1000 100 1 500" armature="0.01" range="-60.0000 60.0000" damping="0.1" stiffness="10" />
          <joint name="Spine_z" type="hinge" pos="0 0 0" axis="0 0 1" user="1000 100 1 500" armature="0.01" range="-60.0000 60.0000" damping="0.1" stiffness="10" />
          <geom type="mesh" mesh="Spine_mesh" density="1000" contype="1" conaffinity="1" />
          <body name="Chest" pos="0.0027 0.0456 0.0394">
            <joint name="Chest_x" type="hinge" pos="0 0 0" axis="1 0 0" user="1000 100 1 500" armature="0.01" range="-60.0000 60.0000" damping="0.1" stiffness="10" />
            <joint name="Chest_y" type="hinge" pos="0 0 0" axis="0 1 0" user="1000 100 1 500" armature="0.01" range="-60.0000 60.0000" damping="0.1" stiffness="10" />
            <joint name="Chest_z" type="hinge" pos="0 0 0" axis="0 0 1" user="1000 100 1 500" armature="0.01" range="-60.0000 60.0000" damping="0.1" stiffness="10" />
            <geom type="mesh" mesh="Chest_mesh" density="1000" contype="1" conaffinity="1" />
            <body name="Neck" pos="0.0098 0.2337 -0.0146">
              <joint name="Neck_x" type="hinge" pos="0 0 0" axis="1 0 0" user="500 50 1 250" armature="0.01" range="-180.0000 180.0000" damping="0.1" stiffness="10" />
              <joint name="Neck_y" type="hinge" pos="0 0 0" axis="0 1 0" user="500 50 1 250" armature="0.01" range="-180.0000 180.0000" damping="0.1" stiffness="10" />
              <joint name="Neck_z" type="hinge" pos="0 0 0" axis="0 0 1" user="500 50 1 250" armature="0.01" range="-180.0000 180.0000" damping="0.1" stiffness="10" />
              <geom type="mesh" mesh="Neck_mesh" density="1000" contype="1" conaffinity="1" />
              <body name="Head" pos="-0.0003 0.0572 0.0674">
                <joint name="Head_x" type="hinge" pos="0 0 0" axis="1 0 0" user="500 50 1 250" armature="0.01" range="-90.0000 90.0000" damping="0.1" stiffness="10" />
                <joint name="Head_y" type="hinge" pos="0 0 0" axis="0 1 0" user="500 50 1 250" armature="0.01" range="-90.0000 90.0000" damping="0.1" stiffness="10" />
                <joint name="Head_z" type="hinge" pos="0 0 0" axis="0 0 1" user="500 50 1 250" armature="0.01" range="-90.0000 90.0000" damping="0.1" stiffness="10" />
                <geom type="mesh" mesh="Head_mesh" density="1000" contype="1" conaffinity="1" />
              </body>
            </body>
            <body name="L_Thorax" pos="0.0973 0.1302 -0.0165">
              <joint name="L_Thorax_x" type="hinge" pos="0 0 0" axis="1 0 0" user="500 50 1 500" armature="0.01" range="-180.0000 180.0000" damping="0.1" stiffness="10" />
              <joint name="L_Thorax_y" type="hinge" pos="0 0 0" axis="0 1 0" user="500 50 1 500" armature="0.01" range="-180.0000 180.0000" damping="0.1" stiffness="10" />
              <joint name="L_Thorax_z" type="hinge" pos="0 0 0" axis="0 0 1" user="500 50 1 500" armature="0.01" range="-180.0000 180.0000" damping="0.1" stiffness="10" />
              <geom type="mesh" mesh="L_Thorax_mesh" density="1000" contype="1" conaffinity="1" />
              <body name="L_Shoulder" pos="0.1008 0.0311 0.005">
                <joint name="L_Shoulder_x" type="hinge" pos="0 0 0" axis="1 0 0" user="500 50 1 500" armature="0.01" range="-180.0000 180.0000" damping="0.1" stiffness="10" />
                <joint name="L_Shoulder_y" type="hinge" pos="0 0 0" axis="0 1 0" user="500 50 1 500" armature="0.01" range="-180.0000 180.0000" damping="0.1" stiffness="10" />
                <joint name="L_Shoulder_z" type="hinge" pos="0 0 0" axis="0 0 1" user="500 50 1 500" armature="0.01" range="-180.0000 180.0000" damping="0.1" stiffness="10" />
                <geom type="mesh" mesh="L_Shoulder_mesh" density="1000" contype="1" conaffinity="1" />
                <body name="L_Elbow" pos="0.2444 -0.1107 -0.0983">
                  <joint name="L_Elbow_x" type="hinge" pos="0 0 0" axis="1 0 0" user="500 50 1 150" armature="0.01" range="-720.0000 720.0000" damping="0.1" stiffness="10" />
                  <joint name="L_Elbow_y" type="hinge" pos="0 0 0" axis="0 1 0" user="500 50 1 150" armature="0.01" range="-720.0000 720.0000" damping="0.1" stiffness="10" />
                  <joint name="L_Elbow_z" type="hinge" pos="0 0 0" axis="0 0 1" user="500 50 1 150" armature="0.01" range="-720.0000 720.0000" damping="0.1" stiffness="10" />
                  <geom type="mesh" mesh="L_Elbow_mesh" density="1000" contype="1" conaffinity="1" />
                  <body name="L_Wrist" pos="0.2276 -0.1218 0.0655">
                    <joint name="L_Wrist_x" type="hinge" pos="0 0 0" axis="1 0 0" user="300 30 1 150" armature="0.01" range="-180.0000 180.0000" damping="0.1" stiffness="10" />
                    <joint name="L_Wrist_y" type="hinge" pos="0 0 0" axis="0 1 0" user="300 30 1 150" armature="0.01" range="-180.0000 180.0000" damping="0.1" stiffness="10" />
                    <joint name="L_Wrist_z" type="hinge" pos="0 0 0" axis="0 0 1" user="300 30 1 150" armature="0.01" range="-180.0000 180.0000" damping="0.1" stiffness="10" />
                    <geom type="mesh" mesh="L_Wrist_mesh" density="1000" contype="1" conaffinity="1" />
                    <body name="L_Hand" pos="0.0755 -0.05 0.0026">
                      <joint name="L_Hand_x" type="hinge" pos="0 0 0" axis="1 0 0" user="300 30 1 150" armature="0.01" range="-180.0000 180.0000" damping="0.1" stiffness="10" />
                      <joint name="L_Hand_y" type="hinge" pos="0 0 0" axis="0 1 0" user="300 30 1 150" armature="0.01" range="-180.0000 180.0000" damping="0.1" stiffness="10" />
                      <joint name="L_Hand_z" type="hinge" pos="0 0 0" axis="0 0 1" user="300 30 1 150" armature="0.01" range="-180.0000 180.0000" damping="0.1" stiffness="10" />
                      <geom type="mesh" mesh="L_Hand_mesh" density="1000" contype="1" conaffinity="1" />
                    </body>
                  </body>
                </body>
              </body>
            </body>
            <body name="R_Thorax" pos="-0.0826 0.1381 -0.0325">
              <joint name="R_Thorax_x" type="hinge" pos="0 0 0" axis="1 0 0" user="500 50 1 150" armature="0.01" range="-180.0000 180.0000" damping="0.1" stiffness="10" />
              <joint name="R_Thorax_y" type="hinge" pos="0 0 0" axis="0 1 0" user="500 50 1 150" armature="0.01" range="-180.0000 180.0000" damping="0.1" stiffness="10" />
              <joint name="R_Thorax_z" type="hinge" pos="0 0 0" axis="0 0 1" user="500 50 1 150" armature="0.01" range="-180.0000 180.0000" damping="0.1" stiffness="10" />
              <geom type="mesh" mesh="R_Thorax_mesh" density="1000" contype="1" conaffinity="1" />
              <body name="R_Shoulder" pos="-0.0861 0.0305 -0.0566">
                <joint name="R_Shoulder_x" type="hinge" pos="0 0 0" axis="1 0 0" user="500 50 1 250" armature="0.01" range="-180.0000 180.0000" damping="0.1" stiffness="10" />
                <joint name="R_Shoulder_y" type="hinge" pos="0 0 0" axis="0 1 0" user="500 50 1 250" armature="0.01" range="-180.0000 180.0000" damping="0.1" stiffness="10" />
                <joint name="R_Shoulder_z" type="hinge" pos="0 0 0" axis="0 0 1" user="500 50 1 250" armature="0.01" range="-180.0000 180.0000" damping="0.1" stiffness="10" />
                <geom type="mesh" mesh="R_Shoulder_mesh" density="1000" contype="1" conaffinity="1" />
                <body name="R_Elbow" pos="-0.2287 0.1219 -0.0962">
                  <joint name="R_Elbow_x" type="hinge" pos="0 0 0" axis="1 0 0" user="500 50 1 150" armature="0.01" range="-720.0000 720.0000" damping="0.1" stiffness="10" />
                  <joint name="R_Elbow_y" type="hinge" pos="0 0 0" axis="0 1 0" user="500 50 1 150" armature="0.01" range="-720.0000 720.0000" damping="0.1" stiffness="10" />
                  <joint name="R_Elbow_z" type="hinge" pos="0 0 0" axis="0 0 1" user="500 50 1 150" armature="0.01" range="-720.0000 720.0000" damping="0.1" stiffness="10" />
                  <geom type="mesh" mesh="R_Elbow_mesh" density="1000" contype="1" conaffinity="1" />
                  <body name="R_Wrist" pos="-0.1741 0.2043 -0.0355">
                    <joint name="R_Wrist_x" type="hinge" pos="0 0 0" axis="1 0 0" user="300 30 1 150" armature="0.01" range="-180.0000 180.0000" damping="0.1" stiffness="10" />
                    <joint name="R_Wrist_y" type="hinge" pos="0 0 0" axis="0 1 0" user="300 30 1 150" armature="0.01" range="-180.0000 180.0000" damping="0.1" stiffness="10" />
                    <joint name="R_Wrist_z" type="hinge" pos="0 0 0" axis="0 0 1" user="300 30 1 150" armature="0.01" range="-180.0000 180.0000" damping="0.1" stiffness="10" />
                    <geom type="mesh" mesh="R_Wrist_mesh" density="1000" contype="1" conaffinity="1" />
                    <body name="R_Hand" pos="-0.0577 0.0683 -0.0051">
                      <joint name="R_Hand_x" type="hinge" pos="0 0 0" axis="1 0 0" user="300 30 1 150" armature="0.01" range="-180.0000 180.0000" damping="0.1" stiffness="10" />
                      <joint name="R_Hand_y" type="hinge" pos="0 0 0" axis="0 1 0" user="300 30 1 150" armature="0.01" range="-180.0000 180.0000" damping="0.1" stiffness="10" />
                      <joint name="R_Hand_z" type="hinge" pos="0 0 0" axis="0 0 1" user="300 30 1 150" armature="0.01" range="-180.0000 180.0000" damping="0.1" stiffness="10" />
                      <geom type="mesh" mesh="R_Hand_mesh" density="1000" contype="1" conaffinity="1" />
                    </body>
                  </body>
                </body>
              </body>
            </body>
          </body>
        </body>
      </body>
    </body>
  </worldbody>
  <actuator>
    <motor name="L_Hip_x" joint="L_Hip_x" gear="1" />
    <motor name="L_Hip_y" joint="L_Hip_y" gear="1" />
    <motor name="L_Hip_z" joint="L_Hip_z" gear="1" />
    <motor name="L_Knee_x" joint="L_Knee_x" gear="1" />
    <motor name="L_Knee_y" joint="L_Knee_y" gear="1" />
    <motor name="L_Knee_z" joint="L_Knee_z" gear="1" />
    <motor name="L_Ankle_x" joint="L_Ankle_x" gear="1" />
    <motor name="L_Ankle_y" joint="L_Ankle_y" gear="1" />
    <motor name="L_Ankle_z" joint="L_Ankle_z" gear="1" />
    <motor name="L_Toe_x" joint="L_Toe_x" gear="1" />
    <motor name="L_Toe_y" joint="L_Toe_y" gear="1" />
    <motor name="L_Toe_z" joint="L_Toe_z" gear="1" />
    <motor name="R_Hip_x" joint="R_Hip_x" gear="1" />
    <motor name="R_Hip_y" joint="R_Hip_y" gear="1" />
    <motor name="R_Hip_z" joint="R_Hip_z" gear="1" />
    <motor name="R_Knee_x" joint="R_Knee_x" gear="1" />
    <motor name="R_Knee_y" joint="R_Knee_y" gear="1" />
    <motor name="R_Knee_z" joint="R_Knee_z" gear="1" />
    <motor name="R_Ankle_x" joint="R_Ankle_x" gear="1" />
    <motor name="R_Ankle_y" joint="R_Ankle_y" gear="1" />
    <motor name="R_Ankle_z" joint="R_Ankle_z" gear="1" />
    <motor name="R_Toe_x" joint="R_Toe_x" gear="1" />
    <motor name="R_Toe_y" joint="R_Toe_y" gear="1" />
    <motor name="R_Toe_z" joint="R_Toe_z" gear="1" />
    <motor name="Torso_x" joint="Torso_x" gear="1" />
    <motor name="Torso_y" joint="Torso_y" gear="1" />
    <motor name="Torso_z" joint="Torso_z" gear="1" />
    <motor name="Spine_x" joint="Spine_x" gear="1" />
    <motor name="Spine_y" joint="Spine_y" gear="1" />
    <motor name="Spine_z" joint="Spine_z" gear="1" />
    <motor name="Chest_x" joint="Chest_x" gear="1" />
    <motor name="Chest_y" joint="Chest_y" gear="1" />
    <motor name="Chest_z" joint="Chest_z" gear="1" />
    <motor name="Neck_x" joint="Neck_x" gear="1" />
    <motor name="Neck_y" joint="Neck_y" gear="1" />
    <motor name="Neck_z" joint="Neck_z" gear="1" />
    <motor name="Head_x" joint="Head_x" gear="1" />
    <motor name="Head_y" joint="Head_y" gear="1" />
    <motor name="Head_z" joint="Head_z" gear="1" />
    <motor name="L_Thorax_x" joint="L_Thorax_x" gear="1" />
    <motor name="L_Thorax_y" joint="L_Thorax_y" gear="1" />
    <motor name="L_Thorax_z" joint="L_Thorax_z" gear="1" />
    <motor name="L_Shoulder_x" joint="L_Shoulder_x" gear="1" />
    <motor name="L_Shoulder_y" joint="L_Shoulder_y" gear="1" />
    <motor name="L_Shoulder_z" joint="L_Shoulder_z" gear="1" />
    <motor name="L_Elbow_x" joint="L_Elbow_x" gear="1" />
    <motor name="L_Elbow_y" joint="L_Elbow_y" gear="1" />
    <motor name="L_Elbow_z" joint="L_Elbow_z" gear="1" />
    <motor name="L_Wrist_x" joint="L_Wrist_x" gear="1" />
    <motor name="L_Wrist_y" joint="L_Wrist_y" gear="1" />
    <motor name="L_Wrist_z" joint="L_Wrist_z" gear="1" />
    <motor name="L_Hand_x" joint="L_Hand_x" gear="1" />
    <motor name="L_Hand_y" joint="L_Hand_y" gear="1" />
    <motor name="L_Hand_z" joint="L_Hand_z" gear="1" />
    <motor name="R_Thorax_x" joint="R_Thorax_x" gear="1" />
    <motor name="R_Thorax_y" joint="R_Thorax_y" gear="1" />
    <motor name="R_Thorax_z" joint="R_Thorax_z" gear="1" />
    <motor name="R_Shoulder_x" joint="R_Shoulder_x" gear="1" />
    <motor name="R_Shoulder_y" joint="R_Shoulder_y" gear="1" />
    <motor name="R_Shoulder_z" joint="R_Shoulder_z" gear="1" />
    <motor name="R_Elbow_x" joint="R_Elbow_x" gear="1" />
    <motor name="R_Elbow_y" joint="R_Elbow_y" gear="1" />
    <motor name="R_Elbow_z" joint="R_Elbow_z" gear="1" />
    <motor name="R_Wrist_x" joint="R_Wrist_x" gear="1" />
    <motor name="R_Wrist_y" joint="R_Wrist_y" gear="1" />
    <motor name="R_Wrist_z" joint="R_Wrist_z" gear="1" />
    <motor name="R_Hand_x" joint="R_Hand_x" gear="1" />
    <motor name="R_Hand_y" joint="R_Hand_y" gear="1" />
    <motor name="R_Hand_z" joint="R_Hand_z" gear="1" />
  </actuator>
  <contact>
    <exclude body1="Torso" body2="Chest" />
    <exclude body1="Head" body2="Chest" />
    <exclude body1="R_Knee" body2="R_Toe" />
    <exclude body1="R_Knee" body2="L_Ankle" />
    <exclude body1="R_Knee" body2="L_Toe" />
    <exclude body1="L_Knee" body2="L_Toe" />
    <exclude body1="L_Knee" body2="R_Ankle" />
    <exclude body1="L_Knee" body2="R_Toe" />
    <exclude body1="L_Shoulder" body2="Chest" />
    <exclude body1="R_Shoulder" body2="Chest" />
  </contact>
  <sensor />
  <size njmax="2500" nconmax="500" />
</mujoco>