<?xml version='1.0' encoding='utf-8'?>
<mujoco model="Humanoid body">
  <asset>
    <texture type="skybox" builtin="gradient" rgb1=".3 .5 .7" rgb2="0 0 0" width="512" height="512" />
    <texture name="body" type="cube" builtin="flat" mark="cross" width="128" height="128" rgb1="0.8 0.6 0.4" rgb2="0.8 0.6 0.4" markrgb="1 1 1" random="0.01" />
    <material name="body" texture="body" texuniform="true" rgba="0.8 0.6 .4 1" />
    <texture name="grid" type="2d" builtin="checker" width="512" height="512" rgb1=".1 .2 .3" rgb2=".2 .3 .4" />
    <material name="grid" texture="grid" texrepeat="1 1" texuniform="true" reflectance=".2" />
    <mesh name="Pelvis_mesh" file="Pelvis.stl" />
    <mesh name="L_Hip_mesh" file="L_Hip.stl" />
    <mesh name="R_Hip_mesh" file="R_Hip.stl" />
    <mesh name="Torso_mesh" file="Torso.stl" />
    <mesh name="L_Knee_mesh" file="L_Knee.stl" />
    <mesh name="R_Knee_mesh" file="R_Knee.stl" />
    <mesh name="Spine_mesh" file="Spine.stl" />
    <mesh name="L_Ankle_mesh" file="L_Ankle.stl" />
    <mesh name="R_Ankle_mesh" file="R_Ankle.stl" />
    <mesh name="Chest_mesh" file="Chest.stl" />
    <mesh name="L_Toe_mesh" file="L_Toe.stl" />
    <mesh name="R_Toe_mesh" file="R_Toe.stl" />
    <mesh name="Neck_mesh" file="Neck.stl" />
    <mesh name="L_Thorax_mesh" file="L_Thorax.stl" />
    <mesh name="R_Thorax_mesh" file="R_Thorax.stl" />
    <mesh name="Head_mesh" file="Head.stl" />
    <mesh name="L_Shoulder_mesh" file="L_Shoulder.stl" />
    <mesh name="R_Shoulder_mesh" file="R_Shoulder.stl" />
    <mesh name="L_Elbow_mesh" file="L_Elbow.stl" />
    <mesh name="R_Elbow_mesh" file="R_Elbow.stl" />
    <mesh name="L_Wrist_mesh" file="L_Wrist.stl" />
    <mesh name="R_Wrist_mesh" file="R_Wrist.stl" />
    <mesh name="L_Hand_mesh" file="L_Hand.stl" />
    <mesh name="R_Hand_mesh" file="R_Hand.stl" />
    </asset>
  <default>
    <motor ctrlrange="-1 1" ctrllimited="true" />
    <default class="body">
      <geom type="capsule" condim="1" friction=".7" solimp=".9 .99 .003" solref=".015 1" material="body" />
      <joint type="hinge" damping=".2" stiffness="1" armature=".01" limited="true" solimplimit="0 .99 .01" />
      <default class="big_joint">
        <joint damping="5" stiffness="100" />
        <default class="big_stiff_joint">
          <joint stiffness="20" />
          </default>
        </default>
      </default>
    </default>
  <visual>
    <map force="0.1" zfar="30" />
    <rgba haze="0.15 0.25 0.35 1" />
    <quality shadowsize="4096" />
    <global offwidth="800" offheight="800" />
    </visual>
  <worldbody>
    <body name="torso" pos="0 0 1.5" childclass="body">
      <camera name="back" pos="-3 0 1" xyaxes="0 -1 0 1 0 2" mode="trackcom" />
      <camera name="side" pos="0 -3 1" xyaxes="1 0 0 0 1 2" mode="trackcom" />
      <freejoint name="root" />
      <body name="head" pos="0 0 .19">
        <camera name="egocentric" pos=".09 0 0" xyaxes="0 -1 0 .1 0 1" fovy="80" />
        <geom type="mesh" mesh="Head_mesh" density="1000.0" contype="7" conaffinity="1" condim="3" friction=".7" solimp=".9 .99 .003" solref=".015 1" />
        </body>
      <body name="lower_waist" pos="-.01 0 -.26">
        <joint name="abdomen_z" pos="0 0 .065" axis="0 0 1" range="-45 45" class="big_stiff_joint" />
        <joint name="abdomen_y" pos="0 0 .065" axis="0 1 0" range="-75 30" class="big_joint" />
        <body name="pelvis" pos="0 0 -.165">
          <joint name="abdomen_x" pos="0 0 .1" axis="1 0 0" range="-35 35" class="big_joint" />
          <body name="right_thigh" pos="0 -.1 -.04">
            <joint name="right_hip_x" axis="1 0 0" range="-25 5" class="big_joint" />
            <joint name="right_hip_z" axis="0 0 1" range="-60 35" class="big_joint" />
            <joint name="right_hip_y" axis="0 1 0" range="-110 20" class="big_stiff_joint" />
            <body name="right_shin" pos="0 .01 -.403">
              <joint name="right_knee" pos="0 0 .02" axis="0 -1 0" range="-160 2" />
              <body name="right_foot" pos="0 0 -.39">
                <joint name="right_ankle_y" pos="0 0 .08" axis="0 1 0" range="-50 50" stiffness="6" />
                <joint name="right_ankle_x" pos="0 0 .04" axis="1 0 .5" range="-50 50" stiffness="3" />
                <geom type="mesh" mesh="R_Ankle_mesh" density="1000.0" contype="7" conaffinity="1" condim="3" friction=".7" solimp=".9 .99 .003" solref=".015 1" />
                </body>
              <geom type="mesh" mesh="R_Knee_mesh" density="1000.0" contype="7" conaffinity="1" condim="3" friction=".7" solimp=".9 .99 .003" solref=".015 1" />
              </body>
            <geom type="mesh" mesh="R_Hip_mesh" density="1000.0" contype="7" conaffinity="1" condim="3" friction=".7" solimp=".9 .99 .003" solref=".015 1" />
            </body>
          <body name="left_thigh" pos="0 .1 -.04">
            <joint name="left_hip_x" axis="-1 0 0" range="-25 5" class="big_joint" />
            <joint name="left_hip_z" axis="0 0 -1" range="-60 35" class="big_joint" />
            <joint name="left_hip_y" axis="0 1 0" range="-110 20" class="big_stiff_joint" />
            <body name="left_shin" pos="0 -.01 -.403">
              <joint name="left_knee" pos="0 0 .02" axis="0 -1 0" range="-160 2" />
              <body name="left_foot" pos="0 0 -.39">
                <joint name="left_ankle_y" pos="0 0 .08" axis="0 1 0" range="-50 50" stiffness="6" />
                <joint name="left_ankle_x" pos="0 0 .04" axis="1 0 .5" range="-50 50" stiffness="3" />
                <geom type="mesh" mesh="L_Ankle_mesh" density="1000.0" contype="7" conaffinity="1" condim="3" friction=".7" solimp=".9 .99 .003" solref=".015 1" />
                </body>
              <geom type="mesh" mesh="L_Knee_mesh" density="1000.0" contype="7" conaffinity="1" condim="3" friction=".7" solimp=".9 .99 .003" solref=".015 1" />
              </body>
            <geom type="mesh" mesh="L_Hip_mesh" density="1000.0" contype="7" conaffinity="1" condim="3" friction=".7" solimp=".9 .99 .003" solref=".015 1" />
            </body>
          <geom type="mesh" mesh="Pelvis_mesh" density="1000.0" contype="7" conaffinity="1" condim="3" friction=".7" solimp=".9 .99 .003" solref=".015 1" />
          </body>
        <geom type="mesh" mesh="Spine_mesh" density="1000.0" contype="7" conaffinity="1" condim="3" friction=".7" solimp=".9 .99 .003" solref=".015 1" />
        </body>
      <body name="right_upper_arm" pos="0 -.17 .06">
        <joint name="right_shoulder1" axis="2 1 1" range="-85 60" />
        <joint name="right_shoulder2" axis="0 -1 1" range="-85 60" />
        <body name="right_lower_arm" pos=".18 -.18 -.18">
          <joint name="right_elbow" axis="0 -1 1" range="-90 50" stiffness="0" />
          <body name="right_hand" pos=".18 .18 .18">
            <geom type="mesh" mesh="R_Hand_mesh" density="1000.0" contype="7" conaffinity="1" condim="3" friction=".7" solimp=".9 .99 .003" solref=".015 1" />
            </body>
          <geom type="mesh" mesh="R_Elbow_mesh" density="1000.0" contype="7" conaffinity="1" condim="3" friction=".7" solimp=".9 .99 .003" solref=".015 1" />
          </body>
        <geom type="mesh" mesh="R_Shoulder_mesh" density="1000.0" contype="7" conaffinity="1" condim="3" friction=".7" solimp=".9 .99 .003" solref=".015 1" />
        </body>
      <body name="left_upper_arm" pos="0 .17 .06">
        <joint name="left_shoulder1" axis="2 -1 1" range="-60 85" />
        <joint name="left_shoulder2" axis="0 1 1" range="-60 85" />
        <body name="left_lower_arm" pos=".18 .18 -.18">
          <joint name="left_elbow" axis="0 -1 -1" range="-90 50" stiffness="0" />
          <body name="left_hand" pos=".18 -.18 .18">
            <geom type="mesh" mesh="L_Hand_mesh" density="1000.0" contype="7" conaffinity="1" condim="3" friction=".7" solimp=".9 .99 .003" solref=".015 1" />
            </body>
          <geom type="mesh" mesh="L_Elbow_mesh" density="1000.0" contype="7" conaffinity="1" condim="3" friction=".7" solimp=".9 .99 .003" solref=".015 1" />
          </body>
        <geom type="mesh" mesh="L_Shoulder_mesh" density="1000.0" contype="7" conaffinity="1" condim="3" friction=".7" solimp=".9 .99 .003" solref=".015 1" />
        </body>
      <geom type="mesh" mesh="Chest_mesh" density="1000.0" contype="7" conaffinity="1" condim="3" friction=".7" solimp=".9 .99 .003" solref=".015 1" />
      </body>
    </worldbody>
  <actuator>
    <motor name="abdomen_y" gear="40" joint="abdomen_y" />
    <motor name="abdomen_z" gear="40" joint="abdomen_z" />
    <motor name="abdomen_x" gear="40" joint="abdomen_x" />
    <motor name="right_hip_x" gear="40" joint="right_hip_x" />
    <motor name="right_hip_z" gear="40" joint="right_hip_z" />
    <motor name="right_hip_y" gear="120" joint="right_hip_y" />
    <motor name="right_knee" gear="80" joint="right_knee" />
    <motor name="right_ankle_x" gear="20" joint="right_ankle_x" />
    <motor name="right_ankle_y" gear="20" joint="right_ankle_y" />
    <motor name="left_hip_x" gear="40" joint="left_hip_x" />
    <motor name="left_hip_z" gear="40" joint="left_hip_z" />
    <motor name="left_hip_y" gear="120" joint="left_hip_y" />
    <motor name="left_knee" gear="80" joint="left_knee" />
    <motor name="left_ankle_x" gear="20" joint="left_ankle_x" />
    <motor name="left_ankle_y" gear="20" joint="left_ankle_y" />
    <motor name="right_shoulder1" gear="20" joint="right_shoulder1" />
    <motor name="right_shoulder2" gear="20" joint="right_shoulder2" />
    <motor name="right_elbow" gear="40" joint="right_elbow" />
    <motor name="left_shoulder1" gear="20" joint="left_shoulder1" />
    <motor name="left_shoulder2" gear="20" joint="left_shoulder2" />
    <motor name="left_elbow" gear="40" joint="left_elbow" />
    </actuator>
  <compiler angle="radian" autolimits="true" meshdir="smpl_meshes/geom" />
  </mujoco>
