<?xml version='1.0' encoding='utf-8'?>
<mujoco model="humanoid">
  <compiler coordinate="local" meshdir="asset/smpl_meshes/geom" />
  <default>
    <joint damping="0.0" armature="0.01" stiffness="1" limited="true" />
    <geom conaffinity="1" condim="3" contype="7" margin="0.001" rgba="0.8 0.6 .4 1" />
  <joint damping="0.01" armature="0.01" stiffness="1" limited="true" /><geom conaffinity="1" condim="3" contype="7" margin="0.001" rgba="0.8 0.6 .4 1" type="box" size="0.01 0.01 0.01" /><joint damping="0.01" armature="0.01" stiffness="1" /></default>
  <asset>
    <texture type="skybox" builtin="gradient" rgb1=".4 .5 .6" rgb2="0 0 0" width="100" height="100" />
    <texture builtin="flat" height="1278" mark="cross" markrgb="1 1 1" name="texgeom" random="0.01" rgb1="0.8 0.6 0.4" rgb2="0.8 0.6 0.4" type="cube" width="127" />
    <texture builtin="checker" height="100" name="texplane" rgb1="0 0 0" rgb2="0.8 0.8 0.8" type="2d" width="100" />
    <material name="MatPlane" reflectance="0.5" shininess="1" specular="1" texrepeat="60 60" texture="texplane" />
    <material name="geom" texture="texgeom" texuniform="true" />
    <mesh file="Pelvis.stl" name="Pelvis_mesh" />
    <mesh file="L_Hip.stl" name="L_Hip_mesh" />
    <mesh file="R_Hip.stl" name="R_Hip_mesh" />
    <mesh file="Torso.stl" name="Torso_mesh" />
    <mesh file="L_Knee.stl" name="L_Knee_mesh" />
    <mesh file="R_Knee.stl" name="R_Knee_mesh" />
    <mesh file="Spine.stl" name="Spine_mesh" />
    <mesh file="L_Ankle.stl" name="L_Ankle_mesh" />
    <mesh file="R_Ankle.stl" name="R_Ankle_mesh" />
    <mesh file="Chest.stl" name="Chest_mesh" />
    <mesh file="L_Toe.stl" name="L_Toe_mesh" />
    <mesh file="R_Toe.stl" name="R_Toe_mesh" />
    <mesh file="Neck.stl" name="Neck_mesh" />
    <mesh file="L_Thorax.stl" name="L_Thorax_mesh" />
    <mesh file="R_Thorax.stl" name="R_Thorax_mesh" />
    <mesh file="Head.stl" name="Head_mesh" />
    <mesh file="L_Shoulder.stl" name="L_Shoulder_mesh" />
    <mesh file="R_Shoulder.stl" name="R_Shoulder_mesh" />
    <mesh file="L_Elbow.stl" name="L_Elbow_mesh" />
    <mesh file="R_Elbow.stl" name="R_Elbow_mesh" />
    <mesh file="L_Wrist.stl" name="L_Wrist_mesh" />
    <mesh file="R_Wrist.stl" name="R_Wrist_mesh" />
    <mesh file="L_Hand.stl" name="L_Hand_mesh" />
    <mesh file="R_Hand.stl" name="R_Hand_mesh" />
  </asset>
  <worldbody>
    <body name="Pelvis" pos="0 0 1.0">
      <freejoint name="Pelvis" />
      <geom type="mesh" mesh="Pelvis_mesh" density="1000" contype="1" conaffinity="1" condim="3" margin="0.001" />
      <body name="L_Hip" pos="0.1173 -0.0572 -0.0071">
        <joint name="L_Hip_x" type="hinge" pos="0 0 0" axis="1 0 0" user="800 80 1 500" armature="0.01" range="-3.14 3.14" damping="0.01" stiffness="1" limited="true" />
        <joint name="L_Hip_y" type="hinge" pos="0 0 0" axis="0 1 0" user="800 80 1 500" armature="0.01" range="-3.14 3.14" damping="0.01" stiffness="1" limited="true" />
        <joint name="L_Hip_z" type="hinge" pos="0 0 0" axis="0 0 1" user="800 80 1 500" armature="0.01" range="-3.14 3.14" damping="0.01" stiffness="1" limited="true" />
        <geom type="mesh" mesh="L_Hip_mesh" density="1000" contype="1" conaffinity="1" condim="3" margin="0.001" />
        <body name="L_Knee" pos="0.3249 -0.1827 0.1434">
          <joint name="L_Knee_x" type="hinge" pos="0 0 0" axis="1 0 0" user="800 80 1 500" armature="0.01" range="-3.14 3.14" damping="0.01" stiffness="1" limited="true" />
          <joint name="L_Knee_y" type="hinge" pos="0 0 0" axis="0 1 0" user="800 80 1 500" armature="0.01" range="-3.14 3.14" damping="0.01" stiffness="1" limited="true" />
          <joint name="L_Knee_z" type="hinge" pos="0 0 0" axis="0 0 1" user="800 80 1 500" armature="0.01" range="-3.14 3.14" damping="0.01" stiffness="1" limited="true" />
          <geom type="mesh" mesh="L_Knee_mesh" density="1000" contype="1" conaffinity="1" condim="3" margin="0.001" />
          <body name="L_Ankle" pos="0.1806 -0.2538 -0.3061">
            <joint name="L_Ankle_x" type="hinge" pos="0 0 0" axis="1 0 0" user="800 80 1 500" armature="0.01" range="-3.14 3.14" damping="0.01" stiffness="1" limited="true" />
            <joint name="L_Ankle_y" type="hinge" pos="0 0 0" axis="0 1 0" user="800 80 1 500" armature="0.01" range="-3.14 3.14" damping="0.01" stiffness="1" limited="true" />
            <joint name="L_Ankle_z" type="hinge" pos="0 0 0" axis="0 0 1" user="800 80 1 500" armature="0.01" range="-3.14 3.14" damping="0.01" stiffness="1" limited="true" />
            <geom density="265.31146" type="box" pos="0.0525 -0.0222 -0.0117" size="0.0867 0.0639 0.0754" quat="1.0000 0.0000 0.0000 0.0000" />
            <body name="L_Toe" pos="0.1233 -0.0501 0.0509">
              <joint name="L_Toe_x" type="hinge" pos="0 0 0" axis="1 0 0" user="500 50 1 500" armature="0.01" range="-3.14 3.14" damping="0.01" stiffness="1" limited="true" />
              <joint name="L_Toe_y" type="hinge" pos="0 0 0" axis="0 1 0" user="500 50 1 500" armature="0.01" range="-3.14 3.14" damping="0.01" stiffness="1" limited="true" />
              <joint name="L_Toe_z" type="hinge" pos="0 0 0" axis="0 0 1" user="500 50 1 500" armature="0.01" range="-3.14 3.14" damping="0.01" stiffness="1" limited="true" />
              <geom density="216.95439" type="box" pos="-0.0708 0.0163 0.0158" size="0.0474 0.0523 0.048" quat="1.0000 0.0000 0.0000 0.0000" />
            </body>
          </body>
        </body>
      </body>
      <body name="R_Hip" pos="-0.0313 -0.1254 -0.0022">
        <joint name="R_Hip_x" type="hinge" pos="0 0 0" axis="1 0 0" user="800 80 1 500" armature="0.01" range="-3.14 3.14" damping="0.01" stiffness="1" limited="true" />
        <joint name="R_Hip_y" type="hinge" pos="0 0 0" axis="0 1 0" user="800 80 1 500" armature="0.01" range="-3.14 3.14" damping="0.01" stiffness="1" limited="true" />
        <joint name="R_Hip_z" type="hinge" pos="0 0 0" axis="0 0 1" user="800 80 1 500" armature="0.01" range="-3.14 3.14" damping="0.01" stiffness="1" limited="true" />
        <geom type="mesh" mesh="R_Hip_mesh" density="1000" contype="1" conaffinity="1" condim="3" margin="0.001" />
        <body name="R_Knee" pos="-0.0297 -0.4065 0.0314">
          <joint name="R_Knee_x" type="hinge" pos="0 0 0" axis="1 0 0" user="800 80 1 500" armature="0.01" range="-3.14 3.14" damping="0.01" stiffness="1" limited="true" />
          <joint name="R_Knee_y" type="hinge" pos="0 0 0" axis="0 1 0" user="800 80 1 500" armature="0.01" range="-3.14 3.14" damping="0.01" stiffness="1" limited="true" />
          <joint name="R_Knee_z" type="hinge" pos="0 0 0" axis="0 0 1" user="800 80 1 500" armature="0.01" range="-3.14 3.14" damping="0.01" stiffness="1" limited="true" />
          <geom type="mesh" mesh="R_Knee_mesh" density="1000" contype="1" conaffinity="1" condim="3" margin="0.001" />
          <body name="R_Ankle" pos="0.074 -0.4246 -0.0776">
            <joint name="R_Ankle_x" type="hinge" pos="0 0 0" axis="1 0 0" user="800 80 1 500" armature="0.01" range="-3.14 3.14" damping="0.01" stiffness="1" limited="true" />
            <joint name="R_Ankle_y" type="hinge" pos="0 0 0" axis="0 1 0" user="800 80 1 500" armature="0.01" range="-3.14 3.14" damping="0.01" stiffness="1" limited="true" />
            <joint name="R_Ankle_z" type="hinge" pos="0 0 0" axis="0 0 1" user="800 80 1 500" armature="0.01" range="-3.14 3.14" damping="0.01" stiffness="1" limited="true" />
            <geom density="295.39114" type="box" pos="-0.0346 -0.0255 0.0229" size="0.0752 0.0578 0.0906" quat="1.0000 0.0000 0.0000 0.0000" />
            <body name="R_Toe" pos="-0.0758 -0.068 0.1027">
              <joint name="R_Toe_x" type="hinge" pos="0 0 0" axis="1 0 0" user="500 50 1 500" armature="0.01" range="-3.14 3.14" damping="0.01" stiffness="1" limited="true" />
              <joint name="R_Toe_y" type="hinge" pos="0 0 0" axis="0 1 0" user="500 50 1 500" armature="0.01" range="-3.14 3.14" damping="0.01" stiffness="1" limited="true" />
              <joint name="R_Toe_z" type="hinge" pos="0 0 0" axis="0 0 1" user="500 50 1 500" armature="0.01" range="-3.14 3.14" damping="0.01" stiffness="1" limited="true" />
              <geom density="361.69293" type="box" pos="0.0412 0.0113 0.0232" size="0.0484 0.0266 0.0581" quat="1.0000 0.0000 0.0000 0.0000" />
            </body>
          </body>
        </body>
      </body>
      <body name="Torso" pos="-0.0527 0.1087 -0.0327">
        <joint name="Torso_x" type="hinge" pos="0 0 0" axis="1 0 0" user="1000 100 1 500" armature="0.01" range="-3.14 3.14" damping="0.01" stiffness="1" limited="true" />
        <joint name="Torso_y" type="hinge" pos="0 0 0" axis="0 1 0" user="1000 100 1 500" armature="0.01" range="-3.14 3.14" damping="0.01" stiffness="1" limited="true" />
        <joint name="Torso_z" type="hinge" pos="0 0 0" axis="0 0 1" user="1000 100 1 500" armature="0.01" range="-3.14 3.14" damping="0.01" stiffness="1" limited="true" />
        <geom type="mesh" mesh="Torso_mesh" density="1000" contype="1" conaffinity="1" condim="3" margin="0.001" />
        <body name="Spine" pos="-0.0509 0.1201 0.0013">
          <joint name="Spine_x" type="hinge" pos="0 0 0" axis="1 0 0" user="1000 100 1 500" armature="0.01" range="-3.14 3.14" damping="0.01" stiffness="1" limited="true" />
          <joint name="Spine_y" type="hinge" pos="0 0 0" axis="0 1 0" user="1000 100 1 500" armature="0.01" range="-3.14 3.14" damping="0.01" stiffness="1" limited="true" />
          <joint name="Spine_z" type="hinge" pos="0 0 0" axis="0 0 1" user="1000 100 1 500" armature="0.01" range="-3.14 3.14" damping="0.01" stiffness="1" limited="true" />
          <geom type="mesh" mesh="Spine_mesh" density="1000" contype="1" conaffinity="1" condim="3" margin="0.001" />
          <body name="Chest" pos="-0.0197 0.0468 0.039">
            <joint name="Chest_x" type="hinge" pos="0 0 0" axis="1 0 0" user="1000 100 1 500" armature="0.01" range="-3.14 3.14" damping="0.01" stiffness="1" limited="true" />
            <joint name="Chest_y" type="hinge" pos="0 0 0" axis="0 1 0" user="1000 100 1 500" armature="0.01" range="-3.14 3.14" damping="0.01" stiffness="1" limited="true" />
            <joint name="Chest_z" type="hinge" pos="0 0 0" axis="0 0 1" user="1000 100 1 500" armature="0.01" range="-3.14 3.14" damping="0.01" stiffness="1" limited="true" />
            <geom type="mesh" mesh="Chest_mesh" density="1000" contype="1" conaffinity="1" condim="3" margin="0.001" />
            <body name="Neck" pos="-0.0946 0.205 -0.0371">
              <joint name="Neck_x" type="hinge" pos="0 0 0" axis="1 0 0" user="500 50 1 250" armature="0.01" range="-3.14 3.14" damping="0.01" stiffness="1" limited="true" />
              <joint name="Neck_y" type="hinge" pos="0 0 0" axis="0 1 0" user="500 50 1 250" armature="0.01" range="-3.14 3.14" damping="0.01" stiffness="1" limited="true" />
              <joint name="Neck_z" type="hinge" pos="0 0 0" axis="0 0 1" user="500 50 1 250" armature="0.01" range="-3.14 3.14" damping="0.01" stiffness="1" limited="true" />
              <geom type="mesh" mesh="Neck_mesh" density="1000" contype="1" conaffinity="1" condim="3" margin="0.001" />
              <body name="Head" pos="-0.0205 0.0497 0.056">
                <joint name="Head_x" type="hinge" pos="0 0 0" axis="1 0 0" user="500 50 1 250" armature="0.01" range="-3.14 3.14" damping="0.01" stiffness="1" limited="true" />
                <joint name="Head_y" type="hinge" pos="0 0 0" axis="0 1 0" user="500 50 1 250" armature="0.01" range="-3.14 3.14" damping="0.01" stiffness="1" limited="true" />
                <joint name="Head_z" type="hinge" pos="0 0 0" axis="0 0 1" user="500 50 1 250" armature="0.01" range="-3.14 3.14" damping="0.01" stiffness="1" limited="true" />
                <geom type="mesh" mesh="Head_mesh" density="1000" contype="1" conaffinity="1" condim="3" margin="0.001" />
              </body>
            </body>
            <body name="L_Thorax" pos="0.0233 0.1572 -0.031">
              <joint name="L_Thorax_x" type="hinge" pos="0 0 0" axis="1 0 0" user="500 50 1 500" armature="0.01" range="-3.14 3.14" damping="0.01" stiffness="1" limited="true" />
              <joint name="L_Thorax_y" type="hinge" pos="0 0 0" axis="0 1 0" user="500 50 1 500" armature="0.01" range="-3.14 3.14" damping="0.01" stiffness="1" limited="true" />
              <joint name="L_Thorax_z" type="hinge" pos="0 0 0" axis="0 0 1" user="500 50 1 500" armature="0.01" range="-3.14 3.14" damping="0.01" stiffness="1" limited="true" />
              <geom type="mesh" mesh="L_Thorax_mesh" density="1000" contype="1" conaffinity="1" condim="3" margin="0.001" />
              <body name="L_Shoulder" pos="0.0779 0.0631 -0.0102">
                <joint name="L_Shoulder_x" type="hinge" pos="0 0 0" axis="1 0 0" user="500 50 1 500" armature="0.01" range="-3.14 3.14" damping="0.01" stiffness="1" limited="true" />
                <joint name="L_Shoulder_y" type="hinge" pos="0 0 0" axis="0 1 0" user="500 50 1 500" armature="0.01" range="-3.14 3.14" damping="0.01" stiffness="1" limited="true" />
                <joint name="L_Shoulder_z" type="hinge" pos="0 0 0" axis="0 0 1" user="500 50 1 500" armature="0.01" range="-3.14 3.14" damping="0.01" stiffness="1" limited="true" />
                <geom type="mesh" mesh="L_Shoulder_mesh" density="1000" contype="1" conaffinity="1" condim="3" margin="0.001" />
                <body name="L_Elbow" pos="0.2522 -0.0118 -0.1256">
                  <joint name="L_Elbow_x" type="hinge" pos="0 0 0" axis="1 0 0" user="500 50 1 150" armature="0.01" range="-3.14 3.14" damping="0.01" stiffness="1" limited="true" />
                  <joint name="L_Elbow_y" type="hinge" pos="0 0 0" axis="0 1 0" user="500 50 1 150" armature="0.01" range="-3.14 3.14" damping="0.01" stiffness="1" limited="true" />
                  <joint name="L_Elbow_z" type="hinge" pos="0 0 0" axis="0 0 1" user="500 50 1 150" armature="0.01" range="-3.14 3.14" damping="0.01" stiffness="1" limited="true" />
                  <geom type="mesh" mesh="L_Elbow_mesh" density="1000" contype="1" conaffinity="1" condim="3" margin="0.001" />
                  <body name="L_Wrist" pos="0.2685 0.0223 0.0185">
                    <joint name="L_Wrist_x" type="hinge" pos="0 0 0" axis="1 0 0" user="300 30 1 150" armature="0.01" range="-3.14 3.14" damping="0.01" stiffness="1" limited="true" />
                    <joint name="L_Wrist_y" type="hinge" pos="0 0 0" axis="0 1 0" user="300 30 1 150" armature="0.01" range="-3.14 3.14" damping="0.01" stiffness="1" limited="true" />
                    <joint name="L_Wrist_z" type="hinge" pos="0 0 0" axis="0 0 1" user="300 30 1 150" armature="0.01" range="-3.14 3.14" damping="0.01" stiffness="1" limited="true" />
                    <geom type="mesh" mesh="L_Wrist_mesh" density="1000" contype="1" conaffinity="1" condim="3" margin="0.001" />
                    <body name="L_Hand" pos="0.0924 -0.0065 -0.0097">
                      <joint name="L_Hand_x" type="hinge" pos="0 0 0" axis="1 0 0" user="300 30 1 150" armature="0.01" range="-3.14 3.14" damping="0.01" stiffness="1" limited="true" />
                      <joint name="L_Hand_y" type="hinge" pos="0 0 0" axis="0 1 0" user="300 30 1 150" armature="0.01" range="-3.14 3.14" damping="0.01" stiffness="1" limited="true" />
                      <joint name="L_Hand_z" type="hinge" pos="0 0 0" axis="0 0 1" user="300 30 1 150" armature="0.01" range="-3.14 3.14" damping="0.01" stiffness="1" limited="true" />
                      <geom type="mesh" mesh="L_Hand_mesh" density="1000" contype="1" conaffinity="1" condim="3" margin="0.001" />
                    </body>
                  </body>
                </body>
              </body>
            </body>
            <body name="R_Thorax" pos="-0.1346 0.0822 -0.0359">
              <joint name="R_Thorax_x" type="hinge" pos="0 0 0" axis="1 0 0" user="500 50 1 150" armature="0.01" range="-3.14 3.14" damping="0.01" stiffness="1" limited="true" />
              <joint name="R_Thorax_y" type="hinge" pos="0 0 0" axis="0 1 0" user="500 50 1 150" armature="0.01" range="-3.14 3.14" damping="0.01" stiffness="1" limited="true" />
              <joint name="R_Thorax_z" type="hinge" pos="0 0 0" axis="0 0 1" user="500 50 1 150" armature="0.01" range="-3.14 3.14" damping="0.01" stiffness="1" limited="true" />
              <geom type="mesh" mesh="R_Thorax_mesh" density="1000" contype="1" conaffinity="1" condim="3" margin="0.001" />
              <body name="R_Shoulder" pos="-0.0965 -0.0452 0.0013">
                <joint name="R_Shoulder_x" type="hinge" pos="0 0 0" axis="1 0 0" user="500 50 1 250" armature="0.01" range="-3.14 3.14" damping="0.01" stiffness="1" limited="true" />
                <joint name="R_Shoulder_y" type="hinge" pos="0 0 0" axis="0 1 0" user="500 50 1 250" armature="0.01" range="-3.14 3.14" damping="0.01" stiffness="1" limited="true" />
                <joint name="R_Shoulder_z" type="hinge" pos="0 0 0" axis="0 0 1" user="500 50 1 250" armature="0.01" range="-3.14 3.14" damping="0.01" stiffness="1" limited="true" />
                <geom type="mesh" mesh="R_Shoulder_mesh" density="1000" contype="1" conaffinity="1" condim="3" margin="0.001" />
                <body name="R_Elbow" pos="-0.0225 -0.253 -0.1133">
                  <joint name="R_Elbow_x" type="hinge" pos="0 0 0" axis="1 0 0" user="500 50 1 150" armature="0.01" range="-3.14 3.14" damping="0.01" stiffness="1" limited="true" />
                  <joint name="R_Elbow_y" type="hinge" pos="0 0 0" axis="0 1 0" user="500 50 1 150" armature="0.01" range="-3.14 3.14" damping="0.01" stiffness="1" limited="true" />
                  <joint name="R_Elbow_z" type="hinge" pos="0 0 0" axis="0 0 1" user="500 50 1 150" armature="0.01" range="-3.14 3.14" damping="0.01" stiffness="1" limited="true" />
                  <geom type="mesh" mesh="R_Elbow_mesh" density="1000" contype="1" conaffinity="1" condim="3" margin="0.001" />
                  <body name="R_Wrist" pos="0.0399 -0.2548 0.1019">
                    <joint name="R_Wrist_x" type="hinge" pos="0 0 0" axis="1 0 0" user="300 30 1 150" armature="0.01" range="-3.14 3.14" damping="0.01" stiffness="1" limited="true" />
                    <joint name="R_Wrist_y" type="hinge" pos="0 0 0" axis="0 1 0" user="300 30 1 150" armature="0.01" range="-3.14 3.14" damping="0.01" stiffness="1" limited="true" />
                    <joint name="R_Wrist_z" type="hinge" pos="0 0 0" axis="0 0 1" user="300 30 1 150" armature="0.01" range="-3.14 3.14" damping="0.01" stiffness="1" limited="true" />
                    <geom type="mesh" mesh="R_Wrist_mesh" density="1000" contype="1" conaffinity="1" condim="3" margin="0.001" />
                    <body name="R_Hand" pos="0.02 -0.0893 0.0202">
                      <joint name="R_Hand_x" type="hinge" pos="0 0 0" axis="1 0 0" user="300 30 1 150" armature="0.01" range="-3.14 3.14" damping="0.01" stiffness="1" limited="true" />
                      <joint name="R_Hand_y" type="hinge" pos="0 0 0" axis="0 1 0" user="300 30 1 150" armature="0.01" range="-3.14 3.14" damping="0.01" stiffness="1" limited="true" />
                      <joint name="R_Hand_z" type="hinge" pos="0 0 0" axis="0 0 1" user="300 30 1 150" armature="0.01" range="-3.14 3.14" damping="0.01" stiffness="1" limited="true" />
                      <geom type="mesh" mesh="R_Hand_mesh" density="1000" contype="1" conaffinity="1" condim="3" margin="0.001" />
                    </body>
                  </body>
                </body>
              </body>
            </body>
          </body>
        </body>
      </body>
    </body>
  </worldbody>
  <actuator>
    <motor name="L_Hip_x" joint="L_Hip_x" gear="1" ctrlrange="-200 200" />
    <motor name="L_Hip_y" joint="L_Hip_y" gear="1" ctrlrange="-200 200" />
    <motor name="L_Hip_z" joint="L_Hip_z" gear="1" ctrlrange="-200 200" />
    <motor name="L_Knee_x" joint="L_Knee_x" gear="1" ctrlrange="-200 200" />
    <motor name="L_Knee_y" joint="L_Knee_y" gear="1" ctrlrange="-200 200" />
    <motor name="L_Knee_z" joint="L_Knee_z" gear="1" ctrlrange="-200 200" />
    <motor name="L_Ankle_x" joint="L_Ankle_x" gear="1" ctrlrange="-200 200" />
    <motor name="L_Ankle_y" joint="L_Ankle_y" gear="1" ctrlrange="-200 200" />
    <motor name="L_Ankle_z" joint="L_Ankle_z" gear="1" ctrlrange="-200 200" />
    <motor name="L_Toe_x" joint="L_Toe_x" gear="1" ctrlrange="-200 200" />
    <motor name="L_Toe_y" joint="L_Toe_y" gear="1" ctrlrange="-200 200" />
    <motor name="L_Toe_z" joint="L_Toe_z" gear="1" ctrlrange="-200 200" />
    <motor name="R_Hip_x" joint="R_Hip_x" gear="1" ctrlrange="-200 200" />
    <motor name="R_Hip_y" joint="R_Hip_y" gear="1" ctrlrange="-200 200" />
    <motor name="R_Hip_z" joint="R_Hip_z" gear="1" ctrlrange="-200 200" />
    <motor name="R_Knee_x" joint="R_Knee_x" gear="1" ctrlrange="-200 200" />
    <motor name="R_Knee_y" joint="R_Knee_y" gear="1" ctrlrange="-200 200" />
    <motor name="R_Knee_z" joint="R_Knee_z" gear="1" ctrlrange="-200 200" />
    <motor name="R_Ankle_x" joint="R_Ankle_x" gear="1" ctrlrange="-200 200" />
    <motor name="R_Ankle_y" joint="R_Ankle_y" gear="1" ctrlrange="-200 200" />
    <motor name="R_Ankle_z" joint="R_Ankle_z" gear="1" ctrlrange="-200 200" />
    <motor name="R_Toe_x" joint="R_Toe_x" gear="1" ctrlrange="-200 200" />
    <motor name="R_Toe_y" joint="R_Toe_y" gear="1" ctrlrange="-200 200" />
    <motor name="R_Toe_z" joint="R_Toe_z" gear="1" ctrlrange="-200 200" />
    <motor name="Torso_x" joint="Torso_x" gear="1" ctrlrange="-200 200" />
    <motor name="Torso_y" joint="Torso_y" gear="1" ctrlrange="-200 200" />
    <motor name="Torso_z" joint="Torso_z" gear="1" ctrlrange="-200 200" />
    <motor name="Spine_x" joint="Spine_x" gear="1" ctrlrange="-200 200" />
    <motor name="Spine_y" joint="Spine_y" gear="1" ctrlrange="-200 200" />
    <motor name="Spine_z" joint="Spine_z" gear="1" ctrlrange="-200 200" />
    <motor name="Chest_x" joint="Chest_x" gear="1" ctrlrange="-200 200" />
    <motor name="Chest_y" joint="Chest_y" gear="1" ctrlrange="-200 200" />
    <motor name="Chest_z" joint="Chest_z" gear="1" ctrlrange="-200 200" />
    <motor name="Neck_x" joint="Neck_x" gear="1" ctrlrange="-200 200" />
    <motor name="Neck_y" joint="Neck_y" gear="1" ctrlrange="-200 200" />
    <motor name="Neck_z" joint="Neck_z" gear="1" ctrlrange="-200 200" />
    <motor name="Head_x" joint="Head_x" gear="1" ctrlrange="-200 200" />
    <motor name="Head_y" joint="Head_y" gear="1" ctrlrange="-200 200" />
    <motor name="Head_z" joint="Head_z" gear="1" ctrlrange="-200 200" />
    <motor name="L_Thorax_x" joint="L_Thorax_x" gear="1" ctrlrange="-200 200" />
    <motor name="L_Thorax_y" joint="L_Thorax_y" gear="1" ctrlrange="-200 200" />
    <motor name="L_Thorax_z" joint="L_Thorax_z" gear="1" ctrlrange="-200 200" />
    <motor name="L_Shoulder_x" joint="L_Shoulder_x" gear="1" ctrlrange="-200 200" />
    <motor name="L_Shoulder_y" joint="L_Shoulder_y" gear="1" ctrlrange="-200 200" />
    <motor name="L_Shoulder_z" joint="L_Shoulder_z" gear="1" ctrlrange="-200 200" />
    <motor name="L_Elbow_x" joint="L_Elbow_x" gear="1" ctrlrange="-200 200" />
    <motor name="L_Elbow_y" joint="L_Elbow_y" gear="1" ctrlrange="-200 200" />
    <motor name="L_Elbow_z" joint="L_Elbow_z" gear="1" ctrlrange="-200 200" />
    <motor name="L_Wrist_x" joint="L_Wrist_x" gear="1" ctrlrange="-200 200" />
    <motor name="L_Wrist_y" joint="L_Wrist_y" gear="1" ctrlrange="-200 200" />
    <motor name="L_Wrist_z" joint="L_Wrist_z" gear="1" ctrlrange="-200 200" />
    <motor name="L_Hand_x" joint="L_Hand_x" gear="1" ctrlrange="-200 200" />
    <motor name="L_Hand_y" joint="L_Hand_y" gear="1" ctrlrange="-200 200" />
    <motor name="L_Hand_z" joint="L_Hand_z" gear="1" ctrlrange="-200 200" />
    <motor name="R_Thorax_x" joint="R_Thorax_x" gear="1" ctrlrange="-200 200" />
    <motor name="R_Thorax_y" joint="R_Thorax_y" gear="1" ctrlrange="-200 200" />
    <motor name="R_Thorax_z" joint="R_Thorax_z" gear="1" ctrlrange="-200 200" />
    <motor name="R_Shoulder_x" joint="R_Shoulder_x" gear="1" ctrlrange="-200 200" />
    <motor name="R_Shoulder_y" joint="R_Shoulder_y" gear="1" ctrlrange="-200 200" />
    <motor name="R_Shoulder_z" joint="R_Shoulder_z" gear="1" ctrlrange="-200 200" />
    <motor name="R_Elbow_x" joint="R_Elbow_x" gear="1" ctrlrange="-200 200" />
    <motor name="R_Elbow_y" joint="R_Elbow_y" gear="1" ctrlrange="-200 200" />
    <motor name="R_Elbow_z" joint="R_Elbow_z" gear="1" ctrlrange="-200 200" />
    <motor name="R_Wrist_x" joint="R_Wrist_x" gear="1" ctrlrange="-200 200" />
    <motor name="R_Wrist_y" joint="R_Wrist_y" gear="1" ctrlrange="-200 200" />
    <motor name="R_Wrist_z" joint="R_Wrist_z" gear="1" ctrlrange="-200 200" />
    <motor name="R_Hand_x" joint="R_Hand_x" gear="1" ctrlrange="-200 200" />
    <motor name="R_Hand_y" joint="R_Hand_y" gear="1" ctrlrange="-200 200" />
    <motor name="R_Hand_z" joint="R_Hand_z" gear="1" ctrlrange="-200 200" />
  </actuator>
  <contact>
    <exclude body1="Torso" body2="Chest" />
    <exclude body1="Head" body2="Chest" />
    <exclude body1="R_Knee" body2="R_Toe" />
    <exclude body1="R_Knee" body2="L_Ankle" />
    <exclude body1="R_Knee" body2="L_Toe" />
    <exclude body1="L_Knee" body2="L_Toe" />
    <exclude body1="L_Knee" body2="R_Ankle" />
    <exclude body1="L_Knee" body2="R_Toe" />
    <exclude body1="L_Shoulder" body2="Chest" />
    <exclude body1="R_Shoulder" body2="Chest" />
  </contact>
  <sensor />
  <size njmax="2500" nconmax="500" />
<compiler angle="radian" autolimits="true" /><statistic meansize="0.05" /></mujoco>